Traceback (most recent call last):
  File "/opt/hostedtoolcache/Python/3.8.16/x64/lib/python3.8/site-packages/jupyter_cache/executors/utils.py", line 51, in single_nb_execution
    executenb(
  File "/opt/hostedtoolcache/Python/3.8.16/x64/lib/python3.8/site-packages/nbclient/client.py", line 1204, in execute
    return NotebookClient(nb=nb, resources=resources, km=km, **kwargs).execute()
  File "/opt/hostedtoolcache/Python/3.8.16/x64/lib/python3.8/site-packages/nbclient/util.py", line 84, in wrapped
    return just_run(coro(*args, **kwargs))
  File "/opt/hostedtoolcache/Python/3.8.16/x64/lib/python3.8/site-packages/nbclient/util.py", line 62, in just_run
    return loop.run_until_complete(coro)
  File "/opt/hostedtoolcache/Python/3.8.16/x64/lib/python3.8/asyncio/base_events.py", line 616, in run_until_complete
    return future.result()
  File "/opt/hostedtoolcache/Python/3.8.16/x64/lib/python3.8/site-packages/nbclient/client.py", line 663, in async_execute
    await self.async_execute_cell(
  File "/opt/hostedtoolcache/Python/3.8.16/x64/lib/python3.8/site-packages/nbclient/client.py", line 965, in async_execute_cell
    await self._check_raise_for_error(cell, cell_index, exec_reply)
  File "/opt/hostedtoolcache/Python/3.8.16/x64/lib/python3.8/site-packages/nbclient/client.py", line 862, in _check_raise_for_error
    raise CellExecutionError.from_cell_and_msg(cell, exec_reply_content)
nbclient.exceptions.CellExecutionError: An error occurred while executing the following cell:
------------------
data = pd.read_csv('https://nxn.se/single-cell-studies/data.tsv', sep='\t')
data['Date'] = data['Date'].pipe(pd.to_datetime, format='%Y%m%d')
data['Reported cells total'] = data['Reported cells total'].str.replace(',', '').map(float)
------------------

[0;31m---------------------------------------------------------------------------[0m
[0;31mKeyError[0m                                  Traceback (most recent call last)
File [0;32m/opt/hostedtoolcache/Python/3.8.16/x64/lib/python3.8/site-packages/pandas/core/indexes/base.py:3802[0m, in [0;36mIndex.get_loc[0;34m(self, key, method, tolerance)[0m
[1;32m   3801[0m [38;5;28;01mtry[39;00m:
[0;32m-> 3802[0m     [38;5;28;01mreturn[39;00m [38;5;28;43mself[39;49m[38;5;241;43m.[39;49m[43m_engine[49m[38;5;241;43m.[39;49m[43mget_loc[49m[43m([49m[43mcasted_key[49m[43m)[49m
[1;32m   3803[0m [38;5;28;01mexcept[39;00m [38;5;167;01mKeyError[39;00m [38;5;28;01mas[39;00m err:

File [0;32m/opt/hostedtoolcache/Python/3.8.16/x64/lib/python3.8/site-packages/pandas/_libs/index.pyx:138[0m, in [0;36mpandas._libs.index.IndexEngine.get_loc[0;34m()[0m

File [0;32m/opt/hostedtoolcache/Python/3.8.16/x64/lib/python3.8/site-packages/pandas/_libs/index.pyx:165[0m, in [0;36mpandas._libs.index.IndexEngine.get_loc[0;34m()[0m

File [0;32mpandas/_libs/hashtable_class_helper.pxi:5745[0m, in [0;36mpandas._libs.hashtable.PyObjectHashTable.get_item[0;34m()[0m

File [0;32mpandas/_libs/hashtable_class_helper.pxi:5753[0m, in [0;36mpandas._libs.hashtable.PyObjectHashTable.get_item[0;34m()[0m

[0;31mKeyError[0m: 'Date'

The above exception was the direct cause of the following exception:

[0;31mKeyError[0m                                  Traceback (most recent call last)
Cell [0;32mIn[2], line 2[0m
[1;32m      1[0m data [38;5;241m=[39m pd[38;5;241m.[39mread_csv([38;5;124m'[39m[38;5;124mhttps://nxn.se/single-cell-studies/data.tsv[39m[38;5;124m'[39m, sep[38;5;241m=[39m[38;5;124m'[39m[38;5;130;01m\t[39;00m[38;5;124m'[39m)
[0;32m----> 2[0m data[[38;5;124m'[39m[38;5;124mDate[39m[38;5;124m'[39m] [38;5;241m=[39m [43mdata[49m[43m[[49m[38;5;124;43m'[39;49m[38;5;124;43mDate[39;49m[38;5;124;43m'[39;49m[43m][49m[38;5;241m.[39mpipe(pd[38;5;241m.[39mto_datetime, [38;5;28mformat[39m[38;5;241m=[39m[38;5;124m'[39m[38;5;124m%[39m[38;5;124mY[39m[38;5;124m%[39m[38;5;124mm[39m[38;5;132;01m%d[39;00m[38;5;124m'[39m)
[1;32m      3[0m data[[38;5;124m'[39m[38;5;124mReported cells total[39m[38;5;124m'[39m] [38;5;241m=[39m data[[38;5;124m'[39m[38;5;124mReported cells total[39m[38;5;124m'[39m][38;5;241m.[39mstr[38;5;241m.[39mreplace([38;5;124m'[39m[38;5;124m,[39m[38;5;124m'[39m, [38;5;124m'[39m[38;5;124m'[39m)[38;5;241m.[39mmap([38;5;28mfloat[39m)

File [0;32m/opt/hostedtoolcache/Python/3.8.16/x64/lib/python3.8/site-packages/pandas/core/frame.py:3807[0m, in [0;36mDataFrame.__getitem__[0;34m(self, key)[0m
[1;32m   3805[0m [38;5;28;01mif[39;00m [38;5;28mself[39m[38;5;241m.[39mcolumns[38;5;241m.[39mnlevels [38;5;241m>[39m [38;5;241m1[39m:
[1;32m   3806[0m     [38;5;28;01mreturn[39;00m [38;5;28mself[39m[38;5;241m.[39m_getitem_multilevel(key)
[0;32m-> 3807[0m indexer [38;5;241m=[39m [38;5;28;43mself[39;49m[38;5;241;43m.[39;49m[43mcolumns[49m[38;5;241;43m.[39;49m[43mget_loc[49m[43m([49m[43mkey[49m[43m)[49m
[1;32m   3808[0m [38;5;28;01mif[39;00m is_integer(indexer):
[1;32m   3809[0m     indexer [38;5;241m=[39m [indexer]

File [0;32m/opt/hostedtoolcache/Python/3.8.16/x64/lib/python3.8/site-packages/pandas/core/indexes/base.py:3804[0m, in [0;36mIndex.get_loc[0;34m(self, key, method, tolerance)[0m
[1;32m   3802[0m     [38;5;28;01mreturn[39;00m [38;5;28mself[39m[38;5;241m.[39m_engine[38;5;241m.[39mget_loc(casted_key)
[1;32m   3803[0m [38;5;28;01mexcept[39;00m [38;5;167;01mKeyError[39;00m [38;5;28;01mas[39;00m err:
[0;32m-> 3804[0m     [38;5;28;01mraise[39;00m [38;5;167;01mKeyError[39;00m(key) [38;5;28;01mfrom[39;00m [38;5;21;01merr[39;00m
[1;32m   3805[0m [38;5;28;01mexcept[39;00m [38;5;167;01mTypeError[39;00m:
[1;32m   3806[0m     [38;5;66;03m# If we have a listlike key, _check_indexing_error will raise[39;00m
[1;32m   3807[0m     [38;5;66;03m#  InvalidIndexError. Otherwise we fall through and re-raise[39;00m
[1;32m   3808[0m     [38;5;66;03m#  the TypeError.[39;00m
[1;32m   3809[0m     [38;5;28mself[39m[38;5;241m.[39m_check_indexing_error(key)

[0;31mKeyError[0m: 'Date'
KeyError: 'Date'

